<?xml version="1.0" ?>
<robot name="partnet_2b37f9944a63ba4b4c3aee8e9d3a6ffa">
	<link name="base"/>
	<link name="link_0">
		<visual name="cabinet_door_surface-9">
			<origin xyz="0.3990322923139692 0.8448920249938966 -0.3754050304999294"/>
			<geometry>
				<mesh filename="textured_objs/original-36.obj"/>
			</geometry>
		</visual>
		<collision>
			<origin xyz="0.3990322923139692 0.8448920249938966 -0.3754050304999294"/>
			<geometry>
				<mesh filename="textured_objs/original-36.obj"/>
			</geometry>
		</collision>
	</link>
	<joint name="joint_0" type="revolute">
		<origin xyz="-0.3990322923139692 -0.8448920249938966 0.3754050304999294"/>
		<axis xyz="0 -1 0"/>
		<child link="link_0"/>
		<parent link="link_3"/>
		<limit lower="0.0" upper="1.6022122533307945"/>
	</joint>
	<link name="link_1">
		<visual name="drawer_front-29">
			<origin xyz="-0.02282584888658025 -0.27756666188211254 0.3846589922904968"/>
			<geometry>
				<mesh filename="textured_objs/original-25.obj"/>
			</geometry>
		</visual>
		<visual name="drawer_front-29">
			<origin xyz="-0.02282584888658025 -0.27756666188211254 0.3846589922904968"/>
			<geometry>
				<mesh filename="textured_objs/original-18.obj"/>
			</geometry>
		</visual>
		<visual name="drawer_side-30">
			<origin xyz="-0.02282584888658025 -0.27756666188211254 0.3846589922904968"/>
			<geometry>
				<mesh filename="textured_objs/original-23.obj"/>
			</geometry>
		</visual>
		<visual name="drawer_side-31">
			<origin xyz="-0.02282584888658025 -0.27756666188211254 0.3846589922904968"/>
			<geometry>
				<mesh filename="textured_objs/original-24.obj"/>
			</geometry>
		</visual>
		<visual name="drawer_back-32">
			<origin xyz="-0.02282584888658025 -0.27756666188211254 0.3846589922904968"/>
			<geometry>
				<mesh filename="textured_objs/original-26.obj"/>
			</geometry>
		</visual>
		<visual name="drawer_bottom-33">
			<origin xyz="-0.02282584888658025 -0.27756666188211254 0.3846589922904968"/>
			<geometry>
				<mesh filename="textured_objs/original-21.obj"/>
			</geometry>
		</visual>
		<visual name="drawer_bottom-33">
			<origin xyz="-0.02282584888658025 -0.27756666188211254 0.3846589922904968"/>
			<geometry>
				<mesh filename="textured_objs/original-22.obj"/>
			</geometry>
		</visual>
		<visual name="drawer_slider-27">
			<origin xyz="-0.02282584888658025 -0.27756666188211254 0.3846589922904968"/>
			<geometry>
				<mesh filename="textured_objs/original-28.obj"/>
			</geometry>
		</visual>
		<visual name="drawer_slider-28">
			<origin xyz="-0.02282584888658025 -0.27756666188211254 0.3846589922904968"/>
			<geometry>
				<mesh filename="textured_objs/original-27.obj"/>
			</geometry>
		</visual>
		<collision>
			<origin xyz="-0.02282584888658025 -0.27756666188211254 0.3846589922904968"/>
			<geometry>
				<mesh filename="textured_objs/original-25.obj"/>
			</geometry>
		</collision>
		<collision>
			<origin xyz="-0.02282584888658025 -0.27756666188211254 0.3846589922904968"/>
			<geometry>
				<mesh filename="textured_objs/original-18.obj"/>
			</geometry>
		</collision>
		<collision>
			<origin xyz="-0.02282584888658025 -0.27756666188211254 0.3846589922904968"/>
			<geometry>
				<mesh filename="textured_objs/original-23.obj"/>
			</geometry>
		</collision>
		<collision>
			<origin xyz="-0.02282584888658025 -0.27756666188211254 0.3846589922904968"/>
			<geometry>
				<mesh filename="textured_objs/original-24.obj"/>
			</geometry>
		</collision>
		<collision>
			<origin xyz="-0.02282584888658025 -0.27756666188211254 0.3846589922904968"/>
			<geometry>
				<mesh filename="textured_objs/original-26.obj"/>
			</geometry>
		</collision>
		<collision>
			<origin xyz="-0.02282584888658025 -0.27756666188211254 0.3846589922904968"/>
			<geometry>
				<mesh filename="textured_objs/original-21.obj"/>
			</geometry>
		</collision>
		<collision>
			<origin xyz="-0.02282584888658025 -0.27756666188211254 0.3846589922904968"/>
			<geometry>
				<mesh filename="textured_objs/original-22.obj"/>
			</geometry>
		</collision>
		<collision>
			<origin xyz="-0.02282584888658025 -0.27756666188211254 0.3846589922904968"/>
			<geometry>
				<mesh filename="textured_objs/original-28.obj"/>
			</geometry>
		</collision>
		<collision>
			<origin xyz="-0.02282584888658025 -0.27756666188211254 0.3846589922904968"/>
			<geometry>
				<mesh filename="textured_objs/original-27.obj"/>
			</geometry>
		</collision>
	</link>
	<joint name="joint_1" type="prismatic">
		<origin xyz="0.02282584888658025 0.27756666188211254 -0.3846589922904968"/>
		<axis xyz="0 0 1"/>
		<child link="link_1"/>
		<parent link="link_3"/>
		<limit lower="0" upper="0.6600000000000001"/>
	</joint>
	<link name="link_2">
		<visual name="drawer_front-18">
			<origin xyz="-0.022883973265345255 -0.5506872722285259 0.38465899229049705"/>
			<geometry>
				<mesh filename="textured_objs/original-49.obj"/>
			</geometry>
		</visual>
		<visual name="drawer_front-18">
			<origin xyz="-0.022883973265345255 -0.5506872722285259 0.38465899229049705"/>
			<geometry>
				<mesh filename="textured_objs/original-42.obj"/>
			</geometry>
		</visual>
		<visual name="drawer_side-19">
			<origin xyz="-0.022883973265345255 -0.5506872722285259 0.38465899229049705"/>
			<geometry>
				<mesh filename="textured_objs/original-48.obj"/>
			</geometry>
		</visual>
		<visual name="drawer_side-20">
			<origin xyz="-0.022883973265345255 -0.5506872722285259 0.38465899229049705"/>
			<geometry>
				<mesh filename="textured_objs/original-47.obj"/>
			</geometry>
		</visual>
		<visual name="drawer_back-21">
			<origin xyz="-0.022883973265345255 -0.5506872722285259 0.38465899229049705"/>
			<geometry>
				<mesh filename="textured_objs/original-50.obj"/>
			</geometry>
		</visual>
		<visual name="drawer_bottom-22">
			<origin xyz="-0.022883973265345255 -0.5506872722285259 0.38465899229049705"/>
			<geometry>
				<mesh filename="textured_objs/original-45.obj"/>
			</geometry>
		</visual>
		<visual name="drawer_bottom-22">
			<origin xyz="-0.022883973265345255 -0.5506872722285259 0.38465899229049705"/>
			<geometry>
				<mesh filename="textured_objs/original-46.obj"/>
			</geometry>
		</visual>
		<visual name="drawer_slider-23">
			<origin xyz="-0.022883973265345255 -0.5506872722285259 0.38465899229049705"/>
			<geometry>
				<mesh filename="textured_objs/original-52.obj"/>
			</geometry>
		</visual>
		<visual name="drawer_slider-24">
			<origin xyz="-0.022883973265345255 -0.5506872722285259 0.38465899229049705"/>
			<geometry>
				<mesh filename="textured_objs/original-51.obj"/>
			</geometry>
		</visual>
		<collision>
			<origin xyz="-0.022883973265345255 -0.5506872722285259 0.38465899229049705"/>
			<geometry>
				<mesh filename="textured_objs/original-49.obj"/>
			</geometry>
		</collision>
		<collision>
			<origin xyz="-0.022883973265345255 -0.5506872722285259 0.38465899229049705"/>
			<geometry>
				<mesh filename="textured_objs/original-42.obj"/>
			</geometry>
		</collision>
		<collision>
			<origin xyz="-0.022883973265345255 -0.5506872722285259 0.38465899229049705"/>
			<geometry>
				<mesh filename="textured_objs/original-48.obj"/>
			</geometry>
		</collision>
		<collision>
			<origin xyz="-0.022883973265345255 -0.5506872722285259 0.38465899229049705"/>
			<geometry>
				<mesh filename="textured_objs/original-47.obj"/>
			</geometry>
		</collision>
		<collision>
			<origin xyz="-0.022883973265345255 -0.5506872722285259 0.38465899229049705"/>
			<geometry>
				<mesh filename="textured_objs/original-50.obj"/>
			</geometry>
		</collision>
		<collision>
			<origin xyz="-0.022883973265345255 -0.5506872722285259 0.38465899229049705"/>
			<geometry>
				<mesh filename="textured_objs/original-45.obj"/>
			</geometry>
		</collision>
		<collision>
			<origin xyz="-0.022883973265345255 -0.5506872722285259 0.38465899229049705"/>
			<geometry>
				<mesh filename="textured_objs/original-46.obj"/>
			</geometry>
		</collision>
		<collision>
			<origin xyz="-0.022883973265345255 -0.5506872722285259 0.38465899229049705"/>
			<geometry>
				<mesh filename="textured_objs/original-52.obj"/>
			</geometry>
		</collision>
		<collision>
			<origin xyz="-0.022883973265345255 -0.5506872722285259 0.38465899229049705"/>
			<geometry>
				<mesh filename="textured_objs/original-51.obj"/>
			</geometry>
		</collision>
	</link>
	<joint name="joint_2" type="prismatic">
		<origin xyz="0.022883973265345255 0.5506872722285259 -0.38465899229049705"/>
		<axis xyz="0 0 1"/>
		<child link="link_2"/>
		<parent link="link_3"/>
		<limit lower="0" upper="0.6600000000000001"/>
	</joint>
	<link name="link_3">
		<visual name="shelf-3">
			<origin xyz="0 0 0"/>
			<geometry>
				<mesh filename="textured_objs/original-34.obj"/>
			</geometry>
		</visual>
		<visual name="vertical_side_panel-11">
			<origin xyz="0 0 0"/>
			<geometry>
				<mesh filename="textured_objs/original-7.obj"/>
			</geometry>
		</visual>
		<visual name="vertical_side_panel-11">
			<origin xyz="0 0 0"/>
			<geometry>
				<mesh filename="textured_objs/original-6.obj"/>
			</geometry>
		</visual>
		<visual name="vertical_side_panel-12">
			<origin xyz="0 0 0"/>
			<geometry>
				<mesh filename="textured_objs/original-4.obj"/>
			</geometry>
		</visual>
		<visual name="vertical_side_panel-12">
			<origin xyz="0 0 0"/>
			<geometry>
				<mesh filename="textured_objs/original-3.obj"/>
			</geometry>
		</visual>
		<visual name="back_panel-13">
			<origin xyz="0 0 0"/>
			<geometry>
				<mesh filename="textured_objs/original-15.obj"/>
			</geometry>
		</visual>
		<visual name="bottom_panel-14">
			<origin xyz="0 0 0"/>
			<geometry>
				<mesh filename="textured_objs/original-10.obj"/>
			</geometry>
		</visual>
		<visual name="bottom_panel-14">
			<origin xyz="0 0 0"/>
			<geometry>
				<mesh filename="textured_objs/original-9.obj"/>
			</geometry>
		</visual>
		<visual name="top_panel-15">
			<origin xyz="0 0 0"/>
			<geometry>
				<mesh filename="textured_objs/original-13.obj"/>
			</geometry>
		</visual>
		<visual name="top_panel-15">
			<origin xyz="0 0 0"/>
			<geometry>
				<mesh filename="textured_objs/original-12.obj"/>
			</geometry>
		</visual>
		<visual name="frame_horizontal_bar-16">
			<origin xyz="0 0 0"/>
			<geometry>
				<mesh filename="textured_objs/original-16.obj"/>
			</geometry>
		</visual>
		<visual name="frame_horizontal_bar-17">
			<origin xyz="0 0 0"/>
			<geometry>
				<mesh filename="textured_objs/original-14.obj"/>
			</geometry>
		</visual>
		<collision>
			<origin xyz="0 0 0"/>
			<geometry>
				<mesh filename="textured_objs/original-34.obj"/>
			</geometry>
		</collision>
		<collision>
			<origin xyz="0 0 0"/>
			<geometry>
				<mesh filename="textured_objs/original-7.obj"/>
			</geometry>
		</collision>
		<collision>
			<origin xyz="0 0 0"/>
			<geometry>
				<mesh filename="textured_objs/original-6.obj"/>
			</geometry>
		</collision>
		<collision>
			<origin xyz="0 0 0"/>
			<geometry>
				<mesh filename="textured_objs/original-4.obj"/>
			</geometry>
		</collision>
		<collision>
			<origin xyz="0 0 0"/>
			<geometry>
				<mesh filename="textured_objs/original-3.obj"/>
			</geometry>
		</collision>
		<collision>
			<origin xyz="0 0 0"/>
			<geometry>
				<mesh filename="textured_objs/original-15.obj"/>
			</geometry>
		</collision>
		<collision>
			<origin xyz="0 0 0"/>
			<geometry>
				<mesh filename="textured_objs/original-10.obj"/>
			</geometry>
		</collision>
		<collision>
			<origin xyz="0 0 0"/>
			<geometry>
				<mesh filename="textured_objs/original-9.obj"/>
			</geometry>
		</collision>
		<collision>
			<origin xyz="0 0 0"/>
			<geometry>
				<mesh filename="textured_objs/original-13.obj"/>
			</geometry>
		</collision>
		<collision>
			<origin xyz="0 0 0"/>
			<geometry>
				<mesh filename="textured_objs/original-12.obj"/>
			</geometry>
		</collision>
		<collision>
			<origin xyz="0 0 0"/>
			<geometry>
				<mesh filename="textured_objs/original-16.obj"/>
			</geometry>
		</collision>
		<collision>
			<origin xyz="0 0 0"/>
			<geometry>
				<mesh filename="textured_objs/original-14.obj"/>
			</geometry>
		</collision>
	</link>
	<joint name="joint_3" type="fixed">
		<origin rpy="1.570796326794897 0 -1.570796326794897" xyz="0 0 0"/>
		<child link="link_3"/>
		<parent link="base"/>
	</joint>
	<link name="link_4">
		<visual name="handle-1">
			<origin xyz="0.3990322923139692 0.8448920249938966 -0.3754050304999294"/>
			<geometry>
				<mesh filename="textured_objs/original-38.obj"/>
			</geometry>
		</visual>
		<visual name="handle-1">
			<origin xyz="0.3990322923139692 0.8448920249938966 -0.3754050304999294"/>
			<geometry>
				<mesh filename="textured_objs/original-39.obj"/>
			</geometry>
		</visual>
		<visual name="handle-1">
			<origin xyz="0.3990322923139692 0.8448920249938966 -0.3754050304999294"/>
			<geometry>
				<mesh filename="textured_objs/original-40.obj"/>
			</geometry>
		</visual>
		<collision>
			<origin xyz="0.3990322923139692 0.8448920249938966 -0.3754050304999294"/>
			<geometry>
				<mesh filename="textured_objs/original-38.obj"/>
			</geometry>
		</collision>
		<collision>
			<origin xyz="0.3990322923139692 0.8448920249938966 -0.3754050304999294"/>
			<geometry>
				<mesh filename="textured_objs/original-39.obj"/>
			</geometry>
		</collision>
		<collision>
			<origin xyz="0.3990322923139692 0.8448920249938966 -0.3754050304999294"/>
			<geometry>
				<mesh filename="textured_objs/original-40.obj"/>
			</geometry>
		</collision>
	</link>
	<joint name="joint_4" type="fixed">
		<origin rpy="0 0 0" xyz="0 0 0"/>
		<child link="link_4"/>
		<parent link="link_0"/>
	</joint>
	<link name="link_5">
		<visual name="handle-1">
			<origin xyz="-0.02282584888658025 -0.27756666188211254 0.3846589922904968"/>
			<geometry>
				<mesh filename="textured_objs/original-30.obj"/>
			</geometry>
		</visual>
		<visual name="handle-1">
			<origin xyz="-0.02282584888658025 -0.27756666188211254 0.3846589922904968"/>
			<geometry>
				<mesh filename="textured_objs/original-31.obj"/>
			</geometry>
		</visual>
		<visual name="handle-1">
			<origin xyz="-0.02282584888658025 -0.27756666188211254 0.3846589922904968"/>
			<geometry>
				<mesh filename="textured_objs/original-32.obj"/>
			</geometry>
		</visual>
		<collision>
			<origin xyz="-0.02282584888658025 -0.27756666188211254 0.3846589922904968"/>
			<geometry>
				<mesh filename="textured_objs/original-30.obj"/>
			</geometry>
		</collision>
		<collision>
			<origin xyz="-0.02282584888658025 -0.27756666188211254 0.3846589922904968"/>
			<geometry>
				<mesh filename="textured_objs/original-31.obj"/>
			</geometry>
		</collision>
		<collision>
			<origin xyz="-0.02282584888658025 -0.27756666188211254 0.3846589922904968"/>
			<geometry>
				<mesh filename="textured_objs/original-32.obj"/>
			</geometry>
		</collision>
	</link>
	<joint name="joint_5" type="fixed">
		<origin rpy="0 0 0" xyz="0 0 0"/>
		<child link="link_5"/>
		<parent link="link_1"/>
	</joint>
	<link name="link_6">
		<visual name="handle-1">
			<origin xyz="-0.022883973265345255 -0.5506872722285259 0.38465899229049705"/>
			<geometry>
				<mesh filename="textured_objs/original-54.obj"/>
			</geometry>
		</visual>
		<visual name="handle-1">
			<origin xyz="-0.022883973265345255 -0.5506872722285259 0.38465899229049705"/>
			<geometry>
				<mesh filename="textured_objs/original-55.obj"/>
			</geometry>
		</visual>
		<visual name="handle-1">
			<origin xyz="-0.022883973265345255 -0.5506872722285259 0.38465899229049705"/>
			<geometry>
				<mesh filename="textured_objs/original-56.obj"/>
			</geometry>
		</visual>
		<collision>
			<origin xyz="-0.022883973265345255 -0.5506872722285259 0.38465899229049705"/>
			<geometry>
				<mesh filename="textured_objs/original-54.obj"/>
			</geometry>
		</collision>
		<collision>
			<origin xyz="-0.022883973265345255 -0.5506872722285259 0.38465899229049705"/>
			<geometry>
				<mesh filename="textured_objs/original-55.obj"/>
			</geometry>
		</collision>
		<collision>
			<origin xyz="-0.022883973265345255 -0.5506872722285259 0.38465899229049705"/>
			<geometry>
				<mesh filename="textured_objs/original-56.obj"/>
			</geometry>
		</collision>
	</link>
	<joint name="joint_6" type="fixed">
		<origin rpy="0 0 0" xyz="0 0 0"/>
		<child link="link_6"/>
		<parent link="link_2"/>
	</joint>
</robot>
